Workbook

Sheet Checklists
B2: Sl No. | C2: Incentive working Checklist Points | D2: Doc Path | E2: Action Jul 2026
C3: Field:-
B4: 1 | C4: Get specific months Incentive Target sheet from concern department head with approval. | D4: Google Sheet | E4: Done
B5: 2 | C5: Download the Consumption reports from Ikigai backend. | D5: Ikigai Report | E5: Done
B6: 3 | C6: Coupon audit done using the google sheet mentained by Data team with Consumption reports. | D6: Google Sheet Mentained by Data team | E6: Done
B7: 4 | C7: After download the Ikigai report, arrange all sales made by BDE's with proper date format to know the coupon applicable for Incentive or not | D7: NA | E7: Done
B8: 5 | C8: Field coupon Analysis report prepare with use of excel tool and also cross check with manually | D8: NA | E8: Done
B9: 6 | C9: Follow the Coupon logic to know the applicability the sale is applicable for Incentive or not | D9: Coupon Logic SOP | E9: Done
B10: 6 | C10: All clubing provision should check properly | D10: NA | E10: Done
B11: 7 | C11: With Effective from Sep 2025 onward Field Incentive calculation,for calculating we should check the ARPU individual wise if it is more than 33000 then that case we will consider which ever is maxmium (Unit or Revenue) if ARPU less than 33000 then we will consider the Revenue achievement to calculate the Incentive. | D11: Having the Email Thread | E11: Done
B12: 8 | C12: Cross verify with updated policy before finalising | D12: NA | E12: Done
B13: 9 | C13: Post Approval from Accounts-Manager send to Business Head and Finance Head | D13: NA
B14: 10 | C14: Check there is any exceptional cases of coupon or Incentive that approved by Management. If there is any case, consider Proper impact in Incentive Calculation and keep the document for future reference. | D14: No such Cases

Sheet Index
B3: S.No | C3: Particulars | D3: Contents | E3: Context | F3: POC Department
B4: 1 | C4: Input | D4: Policy | E4: This is the policy decided and approved by the Management for the | F4: Management
B5: 2 | C5: Input | D5: Target Achieved | E5: Target which are approved from the Management end are incorporated in this sheet. This also includes data related with penalty sales . Data from this sheet is linked to Incentive Report | F5: Management
B6: 3 | C6: Input | D6: Coupon Analysis | E6: This is prepared from the Coupon Analysis Report which is approved from accounts team's end | F6: Accounts Team
B7: 4 | C7: Process | D7: Incentive Report | E7: Incentive Report incorporates all the incentive details for the field sales team and is linked with input files for incentive calculations | F7: Accounts Team
B8: 5 | C8: Process | D8: RM Calculations Pro Rata | E8: This sheet is created to calculate the quarterly pay-out done to the RM's. | F8: Accounts Team
B9: 6 | C9: Output | D9: Incentive Summary | E9: Incentive Summary is the final output sheet which includes a snapshot view of incentives paid to the employee and their annual incentive accumulations. | F9: Accounts Team

Sheet Header Index
B4: S.No | C4: Headers | D4: Remarks | E4: Explanation
B5: 1 | C5: Name | D5: Name of the employee | E5: Name of the Business Development Executive.
B6: =B5+1 -> 2 | C6: Zone | D6: BDE's Zone. | E6: There are five zones namely, North , East , West , South TNKL and South KATS. All BDE along with the colleges are mapped zone wise.
B7: =B6+1 -> 3 | C7: BDE Target Units | D7: Targets decided by the Management. | E7: BDE targets are decided by the Management using Net Active Student count in the targeted colleges.
B8: =B7+1 -> 4 | C8: Winner Units | D8: Decided by the Management | E8: These units decide the performance incentives like Master Blaster , Half yearly incentive winner and best annual performers amongst the BDE's, TM's and RM's.
B9: =B8+1 -> 5 | C9: Rule >80%coupon utilization | D9: 80% of the coupon sales count to be utilized | E9: This rule is mentioned and logically calculated in the Coupon Analysis Sheet.
B10: =B9+1 -> 6 | C10: Refunds | D10: Refunds during the current month | E10: No incentives are paid on the refunds therefore it is represented in a difference column so that BDE wise refunds can be considered.
B11: =B10+1 -> 7 | C11: Achieved Units RM & TM | D11: Achieved Sales count by RM and TM in that month | E11: Achieved count is calculated as per the input sheets and incorporated in this column. This columns indicated the BDE achieve count. These sales count are considered for RM's and TM's incentive calculations.
B12: =B11+1 -> 8 | C12: Achieved units % BDE | D12: Achieved Sales count % | E12: This is the % of column "BDE targets Units " to column "Achieved Units RM & TM".
B13: =B12+1 -> 9 | C13: Target Revenue - NET | D13: BDE's target revenue Without GST | E13: BDE targets which are decided as per the input sheet Target sheets are multiplied by Average Rate Per User (ARPU ) of 29000 to arrive at revenue targets. This does not include GST and ARPU is again decided by the Management
B14: =B13+1 -> 10 | C14: Achieved Revenue - GROSS | D14: Achieved Revenue including GST | E14: Achieved Revenue including GST
B15: =B14+1 -> 11 | C15: Achieved Revenue - NET BDE Rue1 Diqualified | D15: Disqualified amount amongst the Achieved Revenue amount | E15: Coupon Analysis gives the disqualified sales figure ( without GST ) . These figure are then directly linked to the incentive reports to fill out this header
B16: =B15+1 -> 12 | C16: Achieved Revenue - NET BDE | D16: Column 9- column 11 | E16: This is the net revenue generated by the BDE for the month. To calculate this figure we subtract disqualified sales with Gross Sales. All figures are considered w/o GST.
B17: =B16+1 -> 13 | C17: Achieved Revenue % | D17: Revenue % achieved | E17: Achieved Revenue % is calculated by dividing the Achieved Revenue NET by Target Revenue .
... B32: =B31+1 -> 28 | C32: Incentive of the Month | D32: Includes all incentives earned | E32: This column includes the total incentives earned for the month. Total amounts comes here without any 2 lacs incentive restrictions.

Sheet Policy
B1: FY26-27 APJ QTR
B3: ARPU | C3: 33000
B4: BDE/Individual Incentives (Monthly) | D4: (Individual) | L4: First year MBBS units | M4: Incremental slab
B5: 0-49.99% | C5: 0 | L5: 0 | M5: 0
B6: 50-79.99% | C6: 0.005 | L6: 75 | M6: 0.0005
B7: 80-99.99% | C7: 0.01 | L7: 100 | M7: 0.001
B8: 100-129.99% | C8: 0.0225 | L8: 125 | M8: 0.0025
B9: 130% & Above | C9: 0.03
B11: TM/BDM/Sr.BDE - Sub Managers Incentives (Monthly) | D11: (All sub managers under Team Owners) | L11: BDE/Individual Incentives (Monthly) | M11: Slab
B12: 0-74.99% | C12: 0 | L12: 0 | M12: 0
B13: 75-99.99% | C13: 0.001 | L13: 0.5 | M13: 0.005
B14: 100-129.99% | C14: 0.0015 | L14: 0.8 | M14: 0.01
B15: 130% & Above | C15: 0.0025 | L15: 1 | M15: 0.0225
L16: 1.3 | M16: 0.03
B17: Team Owner Incentives (Quarterly) | D17: (11 Team Owners) | L17: TM/BDM/Sr.BDE - Sub Managers Incentives (Monthly) | M17: Slab
B18: 0-74.99% | C18: 0 | L18: 0 | M18: 0
B19: 75-99.99% | C19: 0.0025 | L19: 0.8 | M19: 0.001
B20: 100-129.99% | C20: 0.0035 | L20: 1 | M20: 0.0015
B21: 130% & Above | C21: 0.005 | L21: 1.3 | M21: 0.0025
L22: Team Owner Incentives (Quarterly) | M22: Slab
B23: ZM Incentives (Quarterly) | L23: 0 | M23: 0
B24: 0-74.99% | C24: 0 | L24: 0.8 | M24: 0.0025
B25: 75-99.99% | C25: 0.002 | L25: 1 | M25: 0.0035
B26: 100-129.99% | C26: 0.0025 | L26: 1.3 | M26: 0.005
B27: 130% & Above | C27: 0.0035 | L27: Zonal Managers Incentives (9 Months) | M27: Slab
L28: 0 | M28: 0
L29: 0.8 | M29: 0.002
L30: 1 | M30: 0.0025
L31: 1.3 | M31: 0.0035
B33: RM | C33: Base for April-June | D33: JAS | E33: OND | F33: JFM | G33: Base Revenue | H33: JAS | I33: OND | J33: JFM | L33: Annual Target 26-27 (AMJ Achievement+July to March)
B34: R3-Anjaney | C34: 1950 | D34: =C34*30% -> 585 | E34: =C34*30% -> 585 | F34: =C34*40% -> 780 | G34: =C34*33000 -> 64350000 | H34: =D34*33000 -> 19305000 | I34: =E34*33000 -> 19305000 | J34: =F34*33000 -> 25740000 | K34: R1-Ajeet | L34: Zone | M34: Region | N34: RM | O34: 9 Months Base | P34: 9 Months Revenue | Q34: JAS Base | R34: JAS Revenue | S34: OND Base | T34: OND Revenue | U34: JFM Base | V34: JFM Revenue | W34: AMJ achivement | X34: Annual Revenue Target
B35: R1-Ajeet | C35: 1250 | D35: =C35*30% -> 375 | E35: =C35*30% -> 375 | F35: =C35*40% -> 500 | G35: =C35*33000 -> 41250000 | H35: =D35*33000 -> 12375000 | I35: =E35*33000 -> 12375000 | J35: =F35*33000 -> 16500000 | K35: R2-Independent(Divyansh) | L35: Z1-Divyansh | M35: R1-Ajeet | N35: Ajeet Pandey | O35: 8050 | P35: 265650000 | Q35: 2800 | R35: 92400000 | S35: 3650 | T35: 120450000 | U35: 1600 | V35: 52800000 | W35: 59948037 | X35: 325598037
B36: R2-Akif | C36: 950 | D36: =C36*30% -> 285 | E36: =C36*30% -> 285 | F36: =C36*40% -> 380 | G36: =C36*33000 -> 31350000 | H36: =D36*33000 -> 9405000 | I36: =E36*33000 -> 9405000 | J36: =F36*33000 -> 12540000 | K36: R3-Anjaney | L36: Z1-Divyansh | M36: R2-Akif | N36: Akif Hannan | O36: 5750 | P36: 189750000 | Q36: 2000 | R36: 66000000 | S36: 2600 | T36: 85800000 | U36: 1150 | V36: 37950000 | W36: 22514496 | X36: 212264496
B37: R4-Sohaib | C37: 700 | D37: =C37*30% -> 210 | E37: =C37*30% -> 210 | F37: =C37*40% -> 280 | G37: =C37*33000 -> 23100000 | H37: =D37*33000 -> 6930000 | I37: =E37*33000 -> 6930000 | J37: =F37*33000 -> 9240000 | K37: R4-Susmita | L37: Z5-Independent(Anjaney) | M37: R3-Anjaney | N37: Anjaney Tripathi | O37: 12000 | P37: 396000000 | Q37: 4800 | R37: 158400000 | S37: 4800 | T37: 158400000 | U37: 2400 | V37: 79200000 | W37: 16438504 | X37: 412438504
B38: R5-Susmita | C38: 1600 | D38: =C38*30% -> 480 | E38: =C38*30% -> 480 | F38: =C38*40% -> 640 | G38: =C38*33000 -> 52800000 | H38: =D38*33000 -> 15840000 | I38: =E38*33000 -> 15840000 | J38: =F38*33000 -> 21120000 | K38: R5-Rameez | L38: Z1-Divyansh | M38: R4-Sohaib | N38: Sohaib Ahmed | O38: 4500 | P38: 148500000 | Q38: 1600 | R38: 52800000 | S38: 2000 | T38: 66000000 | U38: 900 | V38: 29700000 | W38: 11461545 | X38: 159961545
B39: R6-Independent(Biswadip) | C39: 1450 | D39: =C39*30% -> 435 | E39: =C39*30% -> 435 | F39: =C39*40% -> 580 | G39: =C39*33000 -> 47850000 | H39: =D39*33000 -> 14355000 | I39: =E39*33000 -> 14355000 | J39: =F39*33000 -> 19140000 | K39: R6-Saif | L39: Z2-Biswadip | M39: R5-Susmita | N39: Susmita Paul | O39: 9550 | P39: 315150000 | Q39: 3350 | R39: 110550000 | S39: 4300 | T39: 141900000 | U39: 1900 | V39: 62700000 | W39: 12339931 | X39: 327489931
B40: R7-Sufiyan | C40: 850 | D40: =C40*30% -> 255 | E40: =C40*30% -> 255 | F40: =C40*40% -> 340 | G40: =C40*33000 -> 28050000 | H40: =D40*33000 -> 8415000 | I40: =E40*33000 -> 8415000 | J40: =F40*33000 -> 11220000 | K40: R7-Independent MH (Rajat) | L40: Z2-Biswadip | M40: R6-Vinod | N40: Vinod Pathania | O40: 10250 | P40: 338250000 | Q40: 3600 | R40: 118800000 | S40: 4600 | T40: 151800000 | U40: 2050 | V40: 67650000 | W40: 10249470 | X40: 348499470
B41: R9-Ajay | C41: 750 | D41: =C41*30% -> 225 | E41: =C41*30% -> 225 | F41: =C41*40% -> 300 | G41: =C41*33000 -> 24750000 | H41: =D41*33000 -> 7425000 | I41: =E41*33000 -> 7425000 | J41: =F41*33000 -> 9900000 | K41: R8-Independent(Rajat) | L41: Z3-Rajat | M41: R7-Sufiyan | N41: Sufiyan Ansari | O41: 5400 | P41: 178200000 | Q41: 1900 | R41: 62700000 | S41: 2400 | T41: 79200000 | U41: 1100 | V41: 36300000 | W41: 17474741 | X41: 195674741
B42: R8-Tauseef | C42: 1100 | D42: =C42*30% -> 330 | E42: =C42*30% -> 330 | F42: =C42*40% -> 440 | G42: =C42*33000 -> 36300000 | H42: =D42*33000 -> 10890000 | I42: =E42*33000 -> 10890000 | J42: =F42*33000 -> 14520000 | K42: R9-Sukanthan | L42: Z3-Rajat | M42: R8-Tauseef | N42: Tauseef Ansari | O42: 7150 | P42: 235950000 | Q42: 2500 | R42: 82500000 | S42: 3200 | T42: 105600000 | U42: 1450 | V42: 47850000 | W42: 11188007 | X42: 247138007
B43: R11-Srinivasan | C43: 1300 | D43: =C43*30% -> 390 | E43: =C43*30% -> 390 | F43: =C43*40% -> 520 | G43: =C43*33000 -> 42900000 | H43: =D43*33000 -> 12870000 | I43: =E43*33000 -> 12870000 | J43: =F43*33000 -> 17160000 | K43: R10-Srinivasan | L43: Z3-Rajat | M43: R9-Ajay | N43: Ajay Kumar | O43: 4600 | P43: 151800000 | Q43: 1400 | R43: 46200000 | S43: 2100 | T43: 69300000 | U43: 1100 | V43: 36300000 | W43: 13394530 | X43: 165194530
...

Sheet Incentive Summary Output
B14: MONTH | E14: April-26 | F14: 46143 | G14: 46174 | H14: 46204 | I14: 46235 | J14: 46266 | K14: 46296 | L14: 46327 | M14: 46357 | N14: 46388 | O14: 46419 | P14: 46447 | Q14: Total | S14: Month | T14: Overall FY 26-27
B15: INCENTIVE (BDE+Sr BDE+TM) | E15: ='Incentive Report- Output'!AF93 -> 1153970.2 | F15: ='Incentive Report- Output'!AF188 -> 1764141.8 | G15: ='Incentive Report- Output'!AF284 -> 1533549.3 | H15: ='Incentive Report- Output'!AF382 -> 1354845.1 | I15: ='Incentive Report- Output'!AF481 -> 22414109 | Q15: =SUM(E15:P15) -> 28220615 | S15: Total Incentive Amount | T15: =Q104 -> 28220615
B16: RM INCENTIVE | E16: ='RM Calculation Pro Rata'!B135 -> 57534.068 | F16: ='RM Calculation Pro Rata'!C135 -> 73900.608 | G16: ='RM Calculation Pro Rata'!D135 -> 78383.449 | H16: ='RM Calculation Pro Rata'!I135 -> 84517.791 | I16: ='RM Calculation Pro Rata'!J135 -> 1245573.4 | Q16: =SUM(E16:P16) -> 1539909.3 | S16: Total Incentive Paid | T16: =AY104 -> 17453056
B17: ZM INCENTIVE | E17: 0 | Q17: =SUM(E17:P17) -> 0 | S17: Accumulation Above 2lacs | T17: =AH104 -> 10767559
B18: REVENUE (Marrow) | E18: ='Incentive Report- Output'!N93+'Incentive Report- Output'!O93 -> 1.0242471e+08 | F18: =+'Incentive Report- Output'!N188+'Incentive Report- Output'!O188 -> 1.4162671e+08 | G18: =+'Incentive Report- Output'!N284+'Incentive Report- Output'!O284 -> 1.2337624e+08 | H18: =+'Incentive Report- Output'!N382+'Incentive Report- Output'!O382 -> 1.0467109e+08 | I18: =+'Incentive Report- Output'!N481+'Incentive Report- Output'!O481 -> 8.353534e+08 | Q18: =SUM(E18:P18) -> 1.3074521e+09
B19: REVENUE (E-gurukul) | E19: 0 | F19: 0 | Q19: =SUM(E19:P19) -> 0 | S19: Accumulation withdrawn | T19: 0
B20: % of Revenue | E20: =(E15+E16+E21)/(E18+E19) -> 0.011828243 | F20: =(F15+F16+F21)/(F18+F19) -> 0.012978078 | G20: =(G15+G16+G21)/(G18+G19) -> 0.01306518 | H20: =(H15+H16+H21)/(H18+H19) -> 0.013751294 | I20: =(I15+I16+I21)/(I18+I19) -> 0.028322961 | Q20: =(Q15+Q16+Q21+Q17)/(Q18+Q19) -> 0.022762229
B21: Rewards ( Trip + Best RM Reward ) | E21: 0 | F21: 0 | Q21: =SUM(E21:P21) -> 0 | S21: =P18/O18 -> #DIV/0! | T21: 1 | U21: =T21-S21 -> #DIV/0!
B22: Penalty If any | E22: 0 | F22: 0 | Q22: =SUM(E22:P22) -> 0
B23: Total Incentive | E23: =SUBTOTAL(9,E25:E103) -> 1153970.2 | F23: =SUBTOTAL(9,F25:F103) -> 1764141.8 | G23: =SUBTOTAL(9,G25:G103) -> 1533549.3 | H23: =SUBTOTAL(9,H25:H103) -> 1354845.1 | I23: =SUBTOTAL(9,I25:I103) -> 22414109 | J23: =SUBTOTAL(9,J25:J103) -> 0 | K23: =SUBTOTAL(9,K25:K103) -> 0 | L23: =SUBTOTAL(9,L25:L103) -> 0 | ... Q23: =SUBTOTAL(9,Q25:Q103) -> 28220615 | S23: Cumulative Incentive | AJ23: Paid Incentive
B24: Employee Name | C24: Employee ID | D24: Designation | E24: April-26 | F24: 46143 | G24: 46174 | H24: 46204 | I24: 46235 | J24: 46266 | K24: 46296 | L24: 46327 | M24: 46357 | N24: 46388 | O24: 46419 | P24: 46447 | Q24: Total Incentive | S24: Employee Name | T24: Employee ID | U24: Designation | V24: April-26 | W24: 46143 | X24: 46174 | Y24: 46204 | Z24: 46235 | AA24: 46266 | AB24: 46296 | AC24: 46327 | AD24: 46357 | AE24: 46388 | AF24: 46419 | AG24: 46447 | AH24: Total Accumulation | AJ24: Employee Name | AK24: Employee ID | AL24: Designation | AM24: April-26 | AN24: 46143 | AO24: 46174 | AP24: 46204 | AQ24: 46235 | AR24: 46266 | AS24: 46296 | AT24: 46327 | AU24: 46357 | AV24: 46388 | AW24: 46419 | AX24: 46447 | AY24: Total Paid
B25: Ajeet Pandey | C25: NHP374 | D25: RM | E25: =SUMIF('Incentive Report- Output'!$B$4:$B$93,'Incentive Summary Output'!C25,'Incentive Report- Output'!$AF$4:$AF$93) -> 5032.9153 | F25: =SUMIF('Incentive Report- Output'!$B$98:$B$188,'Incentive Summary Output'!C25,'Incentive Report- Output'!$AF$98:$AF$188) -> 10166.483 | G25: =SUMIF('Incentive Report- Output'!$B$193:$B$283,'Incentive Summary Output'!C25,'Incentive Report- Output'!$AF$193:$AF$283) -> 6641.3432 | H25: =SUMIF('Incentive Report- Output'!$B$288:$B$382,'Incentive Summary Output'!C25,'Incentive Report- Output'!$AF$288:$AF$382) -> 0 | I25: =SUMIF('Incentive Report- Output'!$B$387:$B$480,'Incentive Summary Output'!C25,'Incentive Report- Output'!$AF$387:$AF$480) -> 544702.83 | Q25: =SUM(E25:P25) -> 566543.57 | S25: Ajeet Pandey | T25: NHP374 | U25: RM | V25: =IF(E25>200000,E25-200000,0) -> 0 | W25: =IF(F25>200000,F25-200000,0) -> 0 | X25: =IF(G25>200000,G25-200000,0) -> 0 | Y25: =IF(H25>200000,H25-200000,0) -> 0 | Z25: =IF(I25>200000,I25-200000,0) -> 344702.83 | AA25: =IF(J25>200000,J25-200000,0) -> 0 | AB25: =IF(K25>200000,K25-200000,0) -> 0 | AC25: =IF(L25>200000,L25-200000,0) -> 0 | ... AG25: =IF(P25>200000,P25-200000,0) -> 0 | AH25: =SUM(V25:AG25) -> 344702.83 | AJ25: Ajeet Pandey | AK25: NHP374 | AL25: RM | AM25: =E25-V25 -> 5032.9153 | AN25: =F25-W25 -> 10166.483 | AO25: =G25-X25 -> 6641.3432 | AP25: =H25-Y25 -> 0 | AQ25: =I25-Z25 -> 200000 | AR25: =J25-AA25 -> 0 | AS25: =K25-AB25 -> 0 | AT25: =L25-AC25 -> 0 | ... AX25: =P25-AG25 -> 0 | AY25: =SUM(AM25:AX25) -> 221840.74
B26: Ankit Madan | C26: NHP291 | D26: BDE | E26: =SUMIF('Incentive Report- Output'!$B$4:$B$93,'Incentive Summary Output'!C26,'Incentive Report- Output'!$AF$4:$AF$93) -> 16384.322 | F26: =SUMIF('Incentive Report- Output'!$B$98:$B$188,'Incentive Summary Output'!C26,'Incentive Report- Output'!$AF$98:$AF$188) -> 9887.8983 | G26: =SUMIF('Incentive Report- Output'!$B$193:$B$283,'Incentive Summary Output'!C26,'Incentive Report- Output'!$AF$193:$AF$283) -> 7365.9195 | H26: =SUMIF('Incentive Report- Output'!$B$288:$B$382,'Incentive Summary Output'!C26,'Incentive Report- Output'!$AF$288:$AF$382) -> 4320.0127 | I26: =SUMIF('Incentive Report- Output'!$B$387:$B$480,'Incentive Summary Output'!C26,'Incentive Report- Output'!$AF$387:$AF$480) -> 482371.07 | Q26: =SUM(E26:P26) -> 520329.22 | S26: Ankit Madan | T26: NHP291 | U26: BDE | V26: =IF(E26>200000,E26-200000,0) -> 0 | W26: =IF(F26>200000,F26-200000,0) -> 0 | X26: =IF(G26>200000,G26-200000,0) -> 0 | Y26: =IF(H26>200000,H26-200000,0) -> 0 | Z26: =IF(I26>200000,I26-200000,0) -> 282371.07 | AA26: =IF(J26>200000,J26-200000,0) -> 0 | AB26: =IF(K26>200000,K26-200000,0) -> 0 | AC26: =IF(L26>200000,L26-200000,0) -> 0 | ... AG26: =IF(P26>200000,P26-200000,0) -> 0 | AH26: =SUM(V26:AG26) -> 282371.07 | AJ26: Ankit Madan | AK26: NHP291 | AL26: BDE | AM26: =E26-V26 -> 16384.322 | AN26: =F26-W26 -> 9887.8983 | AO26: =G26-X26 -> 7365.9195 | AP26: =H26-Y26 -> 4320.0127 | AQ26: =I26-Z26 -> 200000 | AR26: =J26-AA26 -> 0 | AS26: =K26-AB26 -> 0 | AT26: =L26-AC26 -> 0 | ... AX26: =P26-AG26 -> 0 | AY26: =SUM(AM26:AX26) -> 237958.15
B27: Sachin Sharma | C27: NHP698 | D27: BDE | E27: =SUMIF('Incentive Report- Output'!$B$4:$B$93,'Incentive Summary Output'!C27,'Incentive Report- Output'!$AF$4:$AF$93) -> 0 | F27: =SUMIF('Incentive Report- Output'!$B$98:$B$188,'Incentive Summary Output'!C27,'Incentive Report- Output'!$AF$98:$AF$188) -> 65094.96 | G27: =SUMIF('Incentive Report- Output'!$B$193:$B$283,'Incentive Summary Output'!C27,'Incentive Report- Output'!$AF$193:$AF$283) -> 0 | H27: =SUMIF('Incentive Report- Output'!$B$288:$B$382,'Incentive Summary Output'!C27,'Incentive Report- Output'!$AF$288:$AF$382) -> 49999.83 | I27: =SUMIF('Incentive Report- Output'!$B$387:$B$480,'Incentive Summary Output'!C27,'Incentive Report- Output'!$AF$387:$AF$480) -> 418483.45 | Q27: =SUM(E27:P27) -> 533578.24 | S27: Sachin Sharma | T27: NHP698 | U27: BDE | V27: =IF(E27>200000,E27-200000,0) -> 0 | W27: =IF(F27>200000,F27-200000,0) -> 0 | X27: =IF(G27>200000,G27-200000,0) -> 0 | Y27: =IF(H27>200000,H27-200000,0) -> 0 | Z27: =IF(I27>200000,I27-200000,0) -> 218483.45 | AA27: =IF(J27>200000,J27-200000,0) -> 0 | AB27: =IF(K27>200000,K27-200000,0) -> 0 | AC27: =IF(L27>200000,L27-200000,0) -> 0 | ... AG27: =IF(P27>200000,P27-200000,0) -> 0 | AH27: =SUM(V27:AG27) -> 218483.45 | AJ27: Sachin Sharma | AK27: NHP698 | AL27: BDE | AM27: =E27-V27 -> 0 | AN27: =F27-W27 -> 65094.96 | AO27: =G27-X27 -> 0 | AP27: =H27-Y27 -> 49999.83 | AQ27: =I27-Z27 -> 200000 | AR27: =J27-AA27 -> 0 | AS27: =K27-AB27 -> 0 | AT27: =L27-AC27 -> 0 | ... AX27: =P27-AG27 -> 0 | AY27: =SUM(AM27:AX27) -> 315094.79
B28: Shariq Bhat | C28: NHP679 | D28: BDE | E28: =SUMIF('Incentive Report- Output'!$B$4:$B$93,'Incentive Summary Output'!C28,'Incentive Report- Output'!$AF$4:$AF$93) -> 13364.034 | F28: =SUMIF('Incentive Report- Output'!$B$98:$B$188,'Incentive Summary Output'!C28,'Incentive Report- Output'!$AF$98:$AF$188) -> 7496.6144 | G28: =SUMIF('Incentive Report- Output'!$B$193:$B$283,'Incentive Summary Output'!C28,'Incentive Report- Output'!$AF$193:$AF$283) -> 0 | H28: =SUMIF('Incentive Report- Output'!$B$288:$B$382,'Incentive Summary Output'!C28,'Incentive Report- Output'!$AF$288:$AF$382) -> 67499.898 | I28: =SUMIF('Incentive Report- Output'!$B$387:$B$480,'Incentive Summary Output'!C28,'Incentive Report- Output'!$AF$387:$AF$480) -> 451111.98 | Q28: =SUM(E28:P28) -> 539472.53 | S28: Shariq Bhat | T28: NHP679 | U28: BDE | V28: =IF(E28>200000,E28-200000,0) -> 0 | W28: =IF(F28>200000,F28-200000,0) -> 0 | X28: =IF(G28>200000,G28-200000,0) -> 0 | Y28: =IF(H28>200000,H28-200000,0) -> 0 | Z28: =IF(I28>200000,I28-200000,0) -> 251111.98 | AA28: =IF(J28>200000,J28-200000,0) -> 0 | AB28: =IF(K28>200000,K28-200000,0) -> 0 | AC28: =IF(L28>200000,L28-200000,0) -> 0 | ... AG28: =IF(P28>200000,P28-200000,0) -> 0 | AH28: =SUM(V28:AG28) -> 251111.98 | AJ28: Shariq Bhat | AK28: NHP679 | AL28: BDE | AM28: =E28-V28 -> 13364.034 | AN28: =F28-W28 -> 7496.6144 | AO28: =G28-X28 -> 0 | AP28: =H28-Y28 -> 67499.898 | AQ28: =I28-Z28 -> 200000 | AR28: =J28-AA28 -> 0 | AS28: =K28-AB28 -> 0 | AT28: =L28-AC28 -> 0 | ... AX28: =P28-AG28 -> 0 | AY28: =SUM(AM28:AX28) -> 288360.55
B29: Zahid Majeeb | C29: NHP479 | D29: BDE | E29: =SUMIF('Incentive Report- Output'!$B$4:$B$93,'Incentive Summary Output'!C29,'Incentive Report- Output'!$AF$4:$AF$93) -> 7347.2458 | F29: =SUMIF('Incentive Report- Output'!$B$98:$B$188,'Incentive Summary Output'!C29,'Incentive Report- Output'!$AF$98:$AF$188) -> 8391.2924 | G29: =SUMIF('Incentive Report- Output'!$B$193:$B$283,'Incentive Summary Output'!C29,'Incentive Report- Output'!$AF$193:$AF$283) -> 21395.627 | H29: =SUMIF('Incentive Report- Output'!$B$288:$B$382,'Incentive Summary Output'!C29,'Incentive Report- Output'!$AF$288:$AF$382) -> 0 | I29: =SUMIF('Incentive Report- Output'!$B$387:$B$480,'Incentive Summary Output'!C29,'Incentive Report- Output'!$AF$387:$AF$480) -> 449212.12 | Q29: =SUM(E29:P29) -> 486346.28 | S29: Zahid Majeeb | T29: NHP479 | U29: BDE | V29: =IF(E29>200000,E29-200000,0) -> 0 | W29: =IF(F29>200000,F29-200000,0) -> 0 | X29: =IF(G29>200000,G29-200000,0) -> 0 | Y29: =IF(H29>200000,H29-200000,0) -> 0 | Z29: =IF(I29>200000,I29-200000,0) -> 249212.12 | AA29: =IF(J29>200000,J29-200000,0) -> 0 | AB29: =IF(K29>200000,K29-200000,0) -> 0 | AC29: =IF(L29>200000,L29-200000,0) -> 0 | ... AG29: =IF(P29>200000,P29-200000,0) -> 0 | AH29: =SUM(V29:AG29) -> 249212.12 | AJ29: Zahid Majeeb | AK29: NHP479 | AL29: BDE | AM29: =E29-V29 -> 7347.2458 | AN29: =F29-W29 -> 8391.2924 | AO29: =G29-X29 -> 21395.627 | AP29: =H29-Y29 -> 0 | AQ29: =I29-Z29 -> 200000 | AR29: =J29-AA29 -> 0 | AS29: =K29-AB29 -> 0 | AT29: =L29-AC29 -> 0 | ... AX29: =P29-AG29 -> 0 | AY29: =SUM(AM29:AX29) -> 237134.17
B30: Akif Hannan | C30: NHP212 | D30: RM | E30: =SUMIF('Incentive Report- Output'!$B$4:$B$93,'Incentive Summary Output'!C30,'Incentive Report- Output'!$AF$4:$AF$93) -> 4900.9364 | F30: =SUMIF('Incentive Report- Output'!$B$98:$B$188,'Incentive Summary Output'!C30,'Incentive Report- Output'!$AF$98:$AF$188) -> 91033.805 | G30: =SUMIF('Incentive Report- Output'!$B$193:$B$283,'Incentive Summary Output'!C30,'Incentive Report- Output'!$AF$193:$AF$283) -> 89248.907 | H30: =SUMIF('Incentive Report- Output'!$B$288:$B$382,'Incentive Summary Output'!C30,'Incentive Report- Output'!$AF$288:$AF$382) -> 91124.542 | I30: =SUMIF('Incentive Report- Output'!$B$387:$B$480,'Incentive Summary Output'!C30,'Incentive Report- Output'!$AF$387:$AF$480) -> 1178119.6 | Q30: =SUM(E30:P30) -> 1454427.7 | S30: Akif Hannan | T30: NHP212 | U30: RM | V30: =IF(E30>200000,E30-200000,0) -> 0 | W30: =IF(F30>200000,F30-200000,0) -> 0 | X30: =IF(G30>200000,G30-200000,0) -> 0 | Y30: =IF(H30>200000,H30-200000,0) -> 0 | Z30: =IF(I30>200000,I30-200000,0) -> 978119.55 | AA30: =IF(J30>200000,J30-200000,0) -> 0 | AB30: =IF(K30>200000,K30-200000,0) -> 0 | AC30: =IF(L30>200000,L30-200000,0) -> 0 | ... AG30: =IF(P30>200000,P30-200000,0) -> 0 | AH30: =SUM(V30:AG30) -> 978119.55 | AJ30: Akif Hannan | AK30: NHP212 | AL30: RM | AM30: =E30-V30 -> 4900.9364 | AN30: =F30-W30 -> 91033.805 | AO30: =G30-X30 -> 89248.907 | AP30: =H30-Y30 -> 91124.542 | AQ30: =I30-Z30 -> 200000 | AR30: =J30-AA30 -> 0 | AS30: =K30-AB30 -> 0 | AT30: =L30-AC30 -> 0 | ... AX30: =P30-AG30 -> 0 | AY30: =SUM(AM30:AX30) -> 476308.19
B31: Ayush Choubey | C31: NHP727 | D31: BDE | E31: =SUMIF('Incentive Report- Output'!$B$4:$B$93,'Incentive Summary Output'!C31,'Incentive Report- Output'!$AF$4:$AF$93) -> 4968.0847 | F31: =SUMIF('Incentive Report- Output'!$B$98:$B$188,'Incentive Summary Output'!C31,'Incentive Report- Output'!$AF$98:$AF$188) -> 8240.6653 | G31: =SUMIF('Incentive Report- Output'!$B$193:$B$283,'Incentive Summary Output'!C31,'Incentive Report- Output'!$AF$193:$AF$283) -> 7635.1907 | H31: =SUMIF('Incentive Report- Output'!$B$288:$B$382,'Incentive Summary Output'!C31,'Incentive Report- Output'!$AF$288:$AF$382) -> 54812.517 | I31: =SUMIF('Incentive Report- Output'!$B$387:$B$480,'Incentive Summary Output'!C31,'Incentive Report- Output'!$AF$387:$AF$480) -> 172395 | Q31: =SUM(E31:P31) -> 248051.46 | S31: Ayush Choubey | T31: NHP727 | U31: BDE | V31: =IF(E31>200000,E31-200000,0) -> 0 | W31: =IF(F31>200000,F31-200000,0) -> 0 | X31: =IF(G31>200000,G31-200000,0) -> 0 | Y31: =IF(H31>200000,H31-200000,0) -> 0 | Z31: =IF(I31>200000,I31-200000,0) -> 0 | AA31: =IF(J31>200000,J31-200000,0) -> 0 | AB31: =IF(K31>200000,K31-200000,0) -> 0 | AC31: =IF(L31>200000,L31-200000,0) -> 0 | ... AG31: =IF(P31>200000,P31-200000,0) -> 0 | AH31: =SUM(V31:AG31) -> 0 | AJ31: Ayush Choubey | AK31: NHP727 | AL31: BDE | AM31: =E31-V31 -> 4968.0847 | AN31: =F31-W31 -> 8240.6653 | AO31: =G31-X31 -> 7635.1907 | AP31: =H31-Y31 -> 54812.517 | AQ31: =I31-Z31 -> 172395 | AR31: =J31-AA31 -> 0 | AS31: =K31-AB31 -> 0 | AT31: =L31-AC31 -> 0 | ... AX31: =P31-AG31 -> 0 | AY31: =SUM(AM31:AX31) -> 248051.46
B32: Rohit Bharti | C32: NHP395 | D32: BDE | E32: =SUMIF('Incentive Report- Output'!$B$4:$B$93,'Incentive Summary Output'!C32,'Incentive Report- Output'!$AF$4:$AF$93) -> 0 | F32: =SUMIF('Incentive Report- Output'!$B$98:$B$188,'Incentive Summary Output'!C32,'Incentive Report- Output'!$AF$98:$AF$188) -> 8665.8686 | G32: =SUMIF('Incentive Report- Output'!$B$193:$B$283,'Incentive Summary Output'!C32,'Incentive Report- Output'!$AF$193:$AF$283) -> 6801.75 | H32: =SUMIF('Incentive Report- Output'!$B$288:$B$382,'Incentive Summary Output'!C32,'Incentive Report- Output'!$AF$288:$AF$382) -> 6382.2712 | I32: =SUMIF('Incentive Report- Output'!$B$387:$B$480,'Incentive Summary Output'!C32,'Incentive Report- Output'!$AF$387:$AF$480) -> 327714.41 | Q32: =SUM(E32:P32) -> 349564.3 | S32: Rohit Bharti | T32: NHP395 | U32: BDE | V32: =IF(E32>200000,E32-200000,0) -> 0 | W32: =IF(F32>200000,F32-200000,0) -> 0 | X32: =IF(G32>200000,G32-200000,0) -> 0 | Y32: =IF(H32>200000,H32-200000,0) -> 0 | Z32: =IF(I32>200000,I32-200000,0) -> 127714.41 | AA32: =IF(J32>200000,J32-200000,0) -> 0 | AB32: =IF(K32>200000,K32-200000,0) -> 0 | AC32: =IF(L32>200000,L32-200000,0) -> 0 | ... AG32: =IF(P32>200000,P32-200000,0) -> 0 | AH32: =SUM(V32:AG32) -> 127714.41 | AJ32: Rohit Bharti | AK32: NHP395 | AL32: BDE | AM32: =E32-V32 -> 0 | AN32: =F32-W32 -> 8665.8686 | AO32: =G32-X32 -> 6801.75 | AP32: =H32-Y32 -> 6382.2712 | AQ32: =I32-Z32 -> 200000 | AR32: =J32-AA32 -> 0 | AS32: =K32-AB32 -> 0 | AT32: =L32-AC32 -> 0 | ... AX32: =P32-AG32 -> 0 | AY32: =SUM(AM32:AX32) -> 221849.89
B33: Sumit Kumar Singh | C33: NHP709 | D33: BDE | E33: =SUMIF('Incentive Report- Output'!$B$4:$B$93,'Incentive Summary Output'!C33,'Incentive Report- Output'!$AF$4:$AF$93) -> 5893.5085 | F33: =SUMIF('Incentive Report- Output'!$B$98:$B$188,'Incentive Summary Output'!C33,'Incentive Report- Output'!$AF$98:$AF$188) -> 6472.4873 | G33: =SUMIF('Incentive Report- Output'!$B$193:$B$283,'Incentive Summary Output'!C33,'Incentive Report- Output'!$AF$193:$AF$283) -> 7379.678 | H33: =SUMIF('Incentive Report- Output'!$B$288:$B$382,'Incentive Summary Output'!C33,'Incentive Report- Output'!$AF$288:$AF$382) -> 14478.898 | I33: =SUMIF('Incentive Report- Output'!$B$387:$B$480,'Incentive Summary Output'!C33,'Incentive Report- Output'!$AF$387:$AF$480) -> 401696.52 | Q33: =SUM(E33:P33) -> 435921.09 | S33: Sumit Kumar Singh | T33: NHP709 | U33: BDE | V33: =IF(E33>200000,E33-200000,0) -> 0 | W33: =IF(F33>200000,F33-200000,0) -> 0 | X33: =IF(G33>200000,G33-200000,0) -> 0 | Y33: =IF(H33>200000,H33-200000,0) -> 0 | Z33: =IF(I33>200000,I33-200000,0) -> 201696.52 | AA33: =IF(J33>200000,J33-200000,0) -> 0 | AB33: =IF(K33>200000,K33-200000,0) -> 0 | AC33: =IF(L33>200000,L33-200000,0) -> 0 | ... AG33: =IF(P33>200000,P33-200000,0) -> 0 | AH33: =SUM(V33:AG33) -> 201696.52 | AJ33: Sumit Kumar Singh | AK33: NHP709 | AL33: BDE | AM33: =E33-V33 -> 5893.5085 | AN33: =F33-W33 -> 6472.4873 | AO33: =G33-X33 -> 7379.678 | AP33: =H33-Y33 -> 14478.898 | AQ33: =I33-Z33 -> 200000 | AR33: =J33-AA33 -> 0 | AS33: =K33-AB33 -> 0 | AT33: =L33-AC33 -> 0 | ... AX33: =P33-AG33 -> 0 | AY33: =SUM(AM33:AX33) -> 234224.57
B34: Anjaney | C34: NHP144 | D34: RM | E34: =SUMIF('Incentive Report- Output'!$B$4:$B$93,'Incentive Summary Output'!C34,'Incentive Report- Output'!$AF$4:$AF$93) -> 0 | F34: =SUMIF('Incentive Report- Output'!$B$98:$B$188,'Incentive Summary Output'!C34,'Incentive Report- Output'!$AF$98:$AF$188) -> 0 | G34: =SUMIF('Incentive Report- Output'!$B$193:$B$283,'Incentive Summary Output'!C34,'Incentive Report- Output'!$AF$193:$AF$283) -> 0 | H34: =SUMIF('Incentive Report- Output'!$B$288:$B$382,'Incentive Summary Output'!C34,'Incentive Report- Output'!$AF$288:$AF$382) -> 0 | I34: =SUMIF('Incentive Report- Output'!$B$387:$B$480,'Incentive Summary Output'!C34,'Incentive Report- Output'!$AF$387:$AF$480) -> 416765.19 | Q34: =SUM(E34:P34) -> 416765.19 | S34: Anjaney | T34: NHP144 | U34: RM | V34: =IF(E34>200000,E34-200000,0) -> 0 | W34: =IF(F34>200000,F34-200000,0) -> 0 | X34: =IF(G34>200000,G34-200000,0) -> 0 | Y34: =IF(H34>200000,H34-200000,0) -> 0 | Z34: =IF(I34>200000,I34-200000,0) -> 216765.19 | AA34: =IF(J34>200000,J34-200000,0) -> 0 | AB34: =IF(K34>200000,K34-200000,0) -> 0 | AC34: =IF(L34>200000,L34-200000,0) -> 0 | ... AG34: =IF(P34>200000,P34-200000,0) -> 0 | AH34: =SUM(V34:AG34) -> 216765.19 | AJ34: Anjaney | AK34: NHP144 | AL34: RM | AM34: =E34-V34 -> 0 | AN34: =F34-W34 -> 0 | AO34: =G34-X34 -> 0 | AP34: =H34-Y34 -> 0 | AQ34: =I34-Z34 -> 200000 | AR34: =J34-AA34 -> 0 | AS34: =K34-AB34 -> 0 | AT34: =L34-AC34 -> 0 | ... AX34: =P34-AG34 -> 0 | AY34: =SUM(AM34:AX34) -> 200000
B35: Abhishek Sinha | C35: NHP815 | D35: BDE | E35: =SUMIF('Incentive Report- Output'!$B$4:$B$93,'Incentive Summary Output'!C35,'Incentive Report- Output'!$AF$4:$AF$93) -> 13950.508 | F35: =SUMIF('Incentive Report- Output'!$B$98:$B$188,'Incentive Summary Output'!C35,'Incentive Report- Output'!$AF$98:$AF$188) -> 78091.017 | G35: =SUMIF('Incentive Report- Output'!$B$193:$B$283,'Incentive Summary Output'!C35,'Incentive Report- Output'!$AF$193:$AF$283) -> 0 | H35: =SUMIF('Incentive Report- Output'!$B$288:$B$382,'Incentive Summary Output'!C35,'Incentive Report- Output'!$AF$288:$AF$382) -> 0 | I35: =SUMIF('Incentive Report- Output'!$B$387:$B$480,'Incentive Summary Output'!C35,'Incentive Report- Output'!$AF$387:$AF$480) -> 427882.55 | Q35: =SUM(E35:P35) -> 519924.08 | S35: Abhishek Sinha | T35: NHP815 | U35: BDE | V35: =IF(E35>200000,E35-200000,0) -> 0 | W35: =IF(F35>200000,F35-200000,0) -> 0 | X35: =IF(G35>200000,G35-200000,0) -> 0 | Y35: =IF(H35>200000,H35-200000,0) -> 0 | Z35: =IF(I35>200000,I35-200000,0) -> 227882.55 | AA35: =IF(J35>200000,J35-200000,0) -> 0 | AB35: =IF(K35>200000,K35-200000,0) -> 0 | AC35: =IF(L35>200000,L35-200000,0) -> 0 | ... AG35: =IF(P35>200000,P35-200000,0) -> 0 | AH35: =SUM(V35:AG35) -> 227882.55 | AJ35: Abhishek Sinha | AK35: NHP815 | AL35: BDE | AM35: =E35-V35 -> 13950.508 | AN35: =F35-W35 -> 78091.017 | AO35: =G35-X35 -> 0 | AP35: =H35-Y35 -> 0 | AQ35: =I35-Z35 -> 200000 | AR35: =J35-AA35 -> 0 | AS35: =K35-AB35 -> 0 | AT35: =L35-AC35 -> 0 | ... AX35: =P35-AG35 -> 0 | AY35: =SUM(AM35:AX35) -> 292041.53
B36: Adnan Akhtar | C36: NHP170 | D36: BDE | E36: =SUMIF('Incentive Report- Output'!$B$4:$B$93,'Incentive Summary Output'!C36,'Incentive Report- Output'!$AF$4:$AF$93) -> 7714.6441 | F36: =SUMIF('Incentive Report- Output'!$B$98:$B$188,'Incentive Summary Output'!C36,'Incentive Report- Output'!$AF$98:$AF$188) -> 60451.093 | G36: =SUMIF('Incentive Report- Output'!$B$193:$B$283,'Incentive Summary Output'!C36,'Incentive Report- Output'!$AF$193:$AF$283) -> 6702.8178 | H36: =SUMIF('Incentive Report- Output'!$B$288:$B$382,'Incentive Summary Output'!C36,'Incentive Report- Output'!$AF$288:$AF$382) -> 16183.992 | I36: =SUMIF('Incentive Report- Output'!$B$387:$B$480,'Incentive Summary Output'!C36,'Incentive Report- Output'!$AF$387:$AF$480) -> 539778.41 | Q36: =SUM(E36:P36) -> 630830.95 | S36: Adnan Akhtar | T36: NHP170 | U36: BDE | V36: =IF(E36>200000,E36-200000,0) -> 0 | W36: =IF(F36>200000,F36-200000,0) -> 0 | X36: =IF(G36>200000,G36-200000,0) -> 0 | Y36: =IF(H36>200000,H36-200000,0) -> 0 | Z36: =IF(I36>200000,I36-200000,0) -> 339778.41 | AA36: =IF(J36>200000,J36-200000,0) -> 0 | AB36: =IF(K36>200000,K36-200000,0) -> 0 | AC36: =IF(L36>200000,L36-200000,0) -> 0 | ... AG36: =IF(P36>200000,P36-200000,0) -> 0 | AH36: =SUM(V36:AG36) -> 339778.41 | AJ36: Adnan Akhtar | AK36: NHP170 | AL36: BDE | AM36: =E36-V36 -> 7714.6441 | AN36: =F36-W36 -> 60451.093 | AO36: =G36-X36 -> 6702.8178 | AP36: =H36-Y36 -> 16183.992 | AQ36: =I36-Z36 -> 200000 | AR36: =J36-AA36 -> 0 | AS36: =K36-AB36 -> 0 | AT36: =L36-AC36 -> 0 | ... AX36: =P36-AG36 -> 0 | AY36: =SUM(AM36:AX36) -> 291052.55
... B103: Nav Nandh Tej | C103: NHP621 | D103: BDE | E103: =SUMIF('Incentive Report- Output'!$B$4:$B$93,'Incentive Summary Output'!C103,'Incentive Report- Output'!$AF$4:$AF$93) -> 5050.3093 | F103: =SUMIF('Incentive Report- Output'!$B$98:$B$188,'Incentive Summary Output'!C103,'Incentive Report- Output'!$AF$98:$AF$188) -> 0 | G103: =SUMIF('Incentive Report- Output'!$B$193:$B$283,'Incentive Summary Output'!C103,'Incentive Report- Output'!$AF$193:$AF$283) -> 0 | H103: =SUMIF('Incentive Report- Output'!$B$288:$B$382,'Incentive Summary Output'!C103,'Incentive Report- Output'!$AF$288:$AF$382) -> 0 | I103: =SUMIF('Incentive Report- Output'!$B$387:$B$480,'Incentive Summary Output'!C103,'Incentive Report- Output'!$AF$387:$AF$480) -> 0 | Q103: =SUM(E103:P103) -> 5050.3093 | S103: Nav Nandh Tej | T103: NHP621 | U103: BDE | V103: =IF(E103>200000,E103-200000,0) -> 0 | W103: =IF(F103>200000,F103-200000,0) -> 0 | X103: =IF(G103>200000,G103-200000,0) -> 0 | Y103: =IF(H103>200000,H103-200000,0) -> 0 | Z103: =IF(I103>200000,I103-200000,0) -> 0 | AA103: =IF(J103>200000,J103-200000,0) -> 0 | AB103: =IF(K103>200000,K103-200000,0) -> 0 | AC103: =IF(L103>200000,L103-200000,0) -> 0 | ... AG103: =IF(P103>200000,P103-200000,0) -> 0 | AH103: =SUM(V103:AG103) -> 0 | AJ103: Nav Nandh Tej | AK103: NHP621 | AL103: BDE | AM103: =E103-V103 -> 5050.3093 | AN103: =F103-W103 -> 0 | AO103: =G103-X103 -> 0 | AP103: =H103-Y103 -> 0 | AQ103: =I103-Z103 -> 0 | AR103: =J103-AA103 -> 0 | AS103: =K103-AB103 -> 0 | AT103: =L103-AC103 -> 0 | ... AX103: =P103-AG103 -> 0 | AY103: =SUM(AM103:AX103) -> 5050.3093
C104: Total | E104: =SUM(E25:E103) -> 1153970.2 | F104: =SUM(F25:F103) -> 1764141.8 | G104: =SUM(G25:G103) -> 1533549.3 | H104: =SUM(H25:H103) -> 1354845.1 | I104: =SUM(I25:I103) -> 22414109 | J104: =SUM(J25:J103) -> 0 | K104: =SUM(K25:K103) -> 0 | L104: =SUM(L25:L103) -> 0 | ... Q104: =SUM(Q25:Q103) -> 28220615 | T104: Total | V104: =SUM(V25:V103) -> 0 | W104: =SUM(W25:W103) -> 0 | X104: =SUM(X25:X103) -> 0 | Y104: =SUM(Y25:Y103) -> 0 | Z104: =SUM(Z25:Z103) -> 10767559 | AA104: =SUM(AA25:AA103) -> 0 | AB104: =SUM(AB25:AB103) -> 0 | AC104: =SUM(AC25:AC103) -> 0 | ... AH104: =SUM(AH25:AH103) -> 10767559 | AK104: Total | AM104: =SUM(AM25:AM103) -> 1153970.2 | AN104: =SUM(AN25:AN103) -> 1764141.8 | AO104: =SUM(AO25:AO103) -> 1533549.3 | AP104: =SUM(AP25:AP103) -> 1354845.1 | AQ104: =SUM(AQ25:AQ103) -> 11646549 | AR104: =SUM(AR25:AR103) -> 0 | AS104: =SUM(AS25:AS103) -> 0 | AT104: =SUM(AT25:AT103) -> 0 | ... AY104: =SUM(AY25:AY103) -> 17453056

Sheet Target Achieved- Input
A1: 46113 | J1: Gross Sales | Q1: Disqualified Sales | X1: Foundation Sales
A2: Field Sales Targets Arpil 2026-27 | J2: Region | K2: Agent Name | L2: Employee ID | M2: Sum of paid_amount | N2: Sum of paid_amount_*_100/118 | O2: Count of payment_id | Q2: Region | R2: Agent Name | S2: Employee ID | T2: Sum of paid_amount | U2: Sum of paid_amount_*_100/118 | V2: Count of payment_id | X2: Region | Y2: Agent Name | Z2: Employee ID | AA2: Sum of paid_amount | AB2: Sum of paid_amount_*_100/118 | AC2: Count of payment_id
A3: Troopers | B3: Employee IDs | C3: Submanagers | D3: Zone | E3: RM | F3: ZM | G3: April Base | H3: April WC | J3: R1-Ajeet | K3: Ajeet Pandey | L3: NHP374 | M3: 1387763 | N3: 1176070.3 | O3: 37 | Q3: R1-Ajeet | R3: Ajeet Pandey | S3: NHP374 | T3: 199995 | U3: 169487.29 | V3: 5 | X3: R1-Ajeet | Y3: Ajeet Pandey | Z3: NHP374 | AA3: 11998 | AB3: 10167.797 | AC3: 2
A4: Ajeet Pandey | B4: NHP374 | D4: R1-Ajeet | E4: Ajeet Pandey | F4: Divyansh Pandey | G4: 60 | H4: 78 | J4: R1-Ajeet | K4: Ankit Madan | L4: NHP291 | M4: 1999998 | N4: 1694913.6 | O4: 52 | Q4: R1-Ajeet | R4: Ankit Madan | S4: NHP291 | T4: 66648 | U4: 56481.356 | V4: 2 | X4: R1-Ajeet | Y4: Ankit Madan | Z4: NHP291 | AA4: 34995 | AB4: 29656.78 | AC4: 5
A5: Ankit Madan | B5: NHP291 | D5: R1-Ajeet | E5: Ajeet Pandey | F5: Divyansh Pandey | G5: 60 | H5: 78 | J5: R1-Ajeet | K5: Sachin Sharma | L5: NHP698 | M5: 982522 | N5: 832645.76 | O5: 28 | Q5: R1-Ajeet | R5: Sachin Sharma | S5: NHP698 | T5: 141996 | U5: 120335.59 | V5: 4 | X5: R1-Ajeet | Y5: Sachin Sharma | Z5: NHP698 | AA5: 46993 | AB5: 39824.576 | AC5: 7
A6: Sachin Sharma | B6: NHP698 | D6: R1-Ajeet | E6: Ajeet Pandey | F6: Divyansh Pandey | G6: 50 | H6: 65 | J6: R1-Ajeet | K6: Shariq Bhat | L6: NHP679 | M6: 1616955 | N6: 1370300.8 | O6: 45 | Q6: R1-Ajeet | R6: Shariq Bhat | S6: NHP679 | T6: 39999 | U6: 33897.458 | V6: 1 | X6: R1-Ajeet | Y6: Shariq Bhat | Z6: NHP679 | AA6: 5999 | AB6: 5083.8983 | AC6: 1
A7: Shariq Bhat | B7: NHP679 | D7: R1-Ajeet | E7: Ajeet Pandey | F7: Divyansh Pandey | G7: 50 | H7: 65 | J7: R1-Ajeet | K7: Zahid Majeeb | L7: NHP479 | M7: 1773949 | N7: 1503346.6 | O7: 51 | Q7: R1-Ajeet | R7: Zahid Majeeb | S7: NHP479 | T7: 39999 | U7: 33897.458 | V7: 1 | X7: R1-Ajeet | Y7: Zahid Majeeb | Z7: NHP479 | AA7: 0
A8: Zahid Majeeb | B8: NHP479 | D8: R1-Ajeet | E8: Ajeet Pandey | F8: Divyansh Pandey | G8: 60 | H8: 78 | J8: R1-Ajeet Total | M8: 7761187 | N8: 6577277.1 | O8: 213 | Q8: R1-Ajeet Total | T8: 488637 | U8: 414099.15 | V8: 13 | X8: R1-Ajeet Total | AA8: 99985 | AB8: 84733.051 | AC8: 15
A9: Akif Hannan | B9: NHP212 | D9: R2-Akif | E9: Akif Hannan | F9: Divyansh Pandey | G9: 50 | H9: 65 | J9: R2-Akif | K9: Akif Hannan | L9: NHP212 | M9: 1156621 | N9: 980187.29 | O9: 29 | Q9: R2-Akif | R9: Akif Hannan | S9: NHP212 | T9: 0 | X9: R2-Akif | Y9: Akif Hannan | Z9: NHP212 | AA9: 0
A10: Ayush Choubey | B10: NHP727 | D10: R2-Akif | E10: Akif Hannan | F10: Divyansh Pandey | G10: 50 | H10: 65 | J10: R2-Akif | K10: Ayush Choubey | L10: NHP727 | M10: 1225766 | N10: 1038784.7 | O10: 34 | Q10: R2-Akif | R10: Ayush Choubey | S10: NHP727 | T10: 53298 | U10: 45167.797 | V10: 2 | X10: R2-Akif | Y10: Ayush Choubey | Z10: NHP727 | AA10: 29995 | AB10: 25419.492 | AC10: 5
A11: Rohit Bharti | B11: NHP395 | D11: R2-Akif | E11: Akif Hannan | F11: Divyansh Pandey | G11: 60 | H11: 78 | J11: R2-Akif | K11: Rohit Bharti | L11: NHP395 | M11: 1102419 | N11: 934253.39 | O11: 31 | Q11: R2-Akif | R11: Rohit Bharti | S11: NHP395 | T11: 261293 | U11: 221434.75 | V11: 7 | X11: R2-Akif | Y11: Rohit Bharti | Z11: NHP395 | AA11: 35994 | AB11: 30503.39 | AC11: 6
A12: Sumit Kumar | B12: NHP709 | D12: R2-Akif | E12: Akif Hannan | F12: Divyansh Pandey | G12: 50 | H12: 65 | J12: R2-Akif | K12: Sumit Kumar Singh | L12: NHP709 | M12: 1390868 | N12: 1178701.7 | O12: 32 | Q12: R2-Akif | R12: Sumit Kumar Singh | S12: NHP709 | T12: 0 | X12: R2-Akif | Y12: Sumit Kumar Singh | Z12: NHP709 | AA12: 11998 | AB12: 10167.797 | AC12: 2
A13: Abhishek Sinha | B13: NHP815 | D13: R3-Anjaney | E13: Anjaney Tripathi | F13: Divyansh Pandey | G13: 50 | H13: 65 | J13: R2-Akif Total | M13: 4875674 | N13: 4131927.1 | O13: 126 | Q13: R2-Akif Total | T13: 314591 | U13: 266602.54 | V13: 9 | X13: R2-Akif Total | AA13: 77987 | AB13: 66090.678 | AC13: 13
A14: Adnan Akhtar | B14: NHP170 | D14: R3-Anjaney | E14: Anjaney Tripathi | F14: Divyansh Pandey | G14: 70 | H14: 91 | J14: R3-Anjaney | K14: Abhishek Sinha | L14: NHP815 | M14: 1646160 | N14: 1395050.8 | O14: 40 | Q14: R3-Anjaney | R14: Abhishek Sinha | S14: NHP815 | T14: 0 | X14: R3-Anjaney | Y14: Abhishek Sinha | Z14: NHP815 | AA14: 0
A15: Anjaney Tripathi | B15: NHP144 | D15: R3-Anjaney | E15: Anjaney Tripathi | F15: Divyansh Pandey | G15: 50 | H15: 65 | J15: R3-Anjaney | K15: Adnan Akhtar | L15: NHP170 | M15: 2078651 | N15: 1761568.6 | O15: 49 | Q15: R3-Anjaney | R15: Adnan Akhtar | S15: NHP170 | T15: 257995 | U15: 218639.83 | V15: 5 | X15: R3-Anjaney | Y15: Adnan Akhtar | Z15: NHP170 | AA15: 11998 | AB15: 10167.797 | AC15: 2
A16: Anurag Bhargava | B16: NHP290 | D16: R3-Anjaney | E16: Anjaney Tripathi | F16: Divyansh Pandey | G16: 70 | H16: 91 | J16: R3-Anjaney | K16: Anjaney | L16: NHP144 | M16: 567639 | N16: 481050 | O16: 11 | Q16: R3-Anjaney | R16: Anjaney | S16: NHP144 | T16: 567639 | U16: 481050 | V16: 11 | X16: R3-Anjaney | Y16: Anjaney | Z16: NHP144 | AA16: 0
A17: Arshad Khan | B17: NHP561 | C17: Anurag Bhargava | D17: R3-Anjaney | E17: Anjaney Tripathi | F17: Divyansh Pandey | G17: 70 | H17: 91 | J17: R3-Anjaney | K17: Anurag Bhargava | L17: NHP290 | M17: 2314593 | N17: 1961519.5 | O17: 57 | Q17: R3-Anjaney | R17: Anurag Bhargava | S17: NHP290 | T17: 0 | X17: R3-Anjaney | Y17: Anurag Bhargava | Z17: NHP290 | AA17: 23996 | AB17: 20335.593 | AC17: 4
A18: Nikhil D | B18: NHP153 | D18: R3-Anjaney | E18: Anjaney Tripathi | F18: Divyansh Pandey | G18: 70 | H18: 91 | J18: R3-Anjaney | K18: Arshad Khan | L18: NHP561 | M18: 1283266 | N18: 1087513.6 | O18: 34 | Q18: R3-Anjaney | R18: Arshad Khan | S18: NHP561 | T18: 0 | X18: R3-Anjaney | Y18: Arshad Khan | Z18: NHP561 | AA18: 11998 | AB18: 10167.797 | AC18: 2
A19: Sangram Singh | B19: NHP620 | D19: R3-Anjaney | E19: Anjaney Tripathi | F19: Divyansh Pandey | G19: 70 | H19: 91 | J19: R3-Anjaney | K19: Nikhil | L19: NHP153 | M19: 2593239 | N19: 2197660.2 | O19: 61 | Q19: R3-Anjaney | R19: Nikhil | S19: NHP153 | T19: 319994 | U19: 271181.36 | V19: 6 | X19: R3-Anjaney | Y19: Nikhil | Z19: NHP153 | AA19: 11998 | AB19: 10167.797 | AC19: 2
A20: Shubham Vyas | B20: NHP466 | D20: R3-Anjaney | E20: Anjaney Tripathi | F20: Divyansh Pandey | G20: 60 | H20: 78 | J20: R3-Anjaney | K20: Shubham Vyas | L20: NHP466 | M20: 832680 | N20: 705661.02 | O20: 20 | Q20: R3-Anjaney | R20: Shubham Vyas | S20: NHP466 | T20: 101797 | U20: 86268.644 | V20: 3 | X20: R3-Anjaney | Y20: Shubham Vyas | Z20: NHP466 | AA20: 5999 | AB20: 5083.8983 | AC20: 1
A21: Adarsh Kumar | B21: NHP670 | D21: R4-Sohaib | E21: Sohaib Ahmed | F21: Divyansh Pandey | G21: 50 | H21: 65 | J21: R3-Anjaney | K21: Sangram Singh | L21: NHP620 | M21: 1826908 | N21: 1548227.1 | O21: 42 | Q21: R3-Anjaney | R21: Sangram Singh | S21: NHP620 | T21: 0 | X21: R3-Anjaney | Y21: Sangram Singh | Z21: NHP620 | AA21: 20997 | AB21: 17794.068 | AC21: 3
A22: Ankit Jha | B22: NHP672 | D22: R4-Sohaib | E22: Sohaib Ahmed | F22: Divyansh Pandey | G22: 50 | H22: 65 | J22: R3-Anjaney Total | M22: 13143136 | N22: 11138251 | O22: 314 | Q22: R3-Anjaney Total | T22: 1247425 | U22: 1057139.8 | V22: 25 | X22: R3-Anjaney Total | AA22: 86986 | AB22: 73716.949 | AC22: 14
A23: Sohaib Ahmed | B23: NHP173 | D23: R4-Sohaib | E23: Sohaib Ahmed | F23: Divyansh Pandey | G23: 60 | H23: 78 | J23: R4-Sohaib | K23: Adarsh Kumar | L23: NHP670 | M23: 1096521 | N23: 929255.08 | O23: 29 | Q23: R4-Sohaib | R23: Adarsh Kumar | S23: NHP670 | T23: 136446 | U23: 115632.2 | V23: 4 | X23: R4-Sohaib | Y23: Adarsh Kumar | Z23: NHP670 | AA23: 30995 | AB23: 26266.949 | AC23: 5
A24: Masud Rana | B24: NHP386 | D24: R5-Susmita | E24: Susmita Paul | F24: Biswadip Sarkar | G24: 65 | H24: 84.5 | J24: R4-Sohaib | K24: Ankit Jha | L24: NHP672 | M24: 815227 | N24: 690870.34 | O24: 23 | Q24: R4-Sohaib | R24: Ankit Jha | S24: NHP672 | T24: 229794 | U24: 194740.68 | V24: 6 | X24: R4-Sohaib | Y24: Ankit Jha | Z24: NHP672 | AA24: 23996 | AB24: 20335.593 | AC24: 4
A25: Nildeep Dasgupta | B25: NHP807 | D25: R5-Susmita | E25: Susmita Paul | F25: Biswadip Sarkar | G25: 30 | H25: 39 | J25: R4-Sohaib | K25: Sohaib Ahmed | L25: NHP173 | M25: 1818156 | N25: 1540810.2 | O25: 44 | Q25: R4-Sohaib | R25: Sohaib Ahmed | S25: NHP173 | T25: 119997 | U25: 101692.37 | V25: 3 | X25: R4-Sohaib | Y25: Sohaib Ahmed | Z25: NHP173 | AA25: 30995 | AB25: 26266.949 | AC25: 5
A26: Nilotpal Sharma | B26: NHP675 | C26: Masud Rana | D26: R5-Susmita | E26: Susmita Paul | F26: Biswadip Sarkar | G26: 50 | H26: 65 | J26: R4-Sohaib Total | M26: 3729904 | N26: 3160935.6 | O26: 96 | Q26: R4-Sohaib Total | T26: 486237 | U26: 412065.25 | V26: 13 | X26: R4-Sohaib Total | AA26: 85986 | AB26: 72869.492 | AC26: 14
A27: Sambit Kumar | B27: NHP717 | C27: Subash Debnath | D27: R5-Susmita | E27: Susmita Paul | F27: Biswadip Sarkar | G27: 60 | H27: 78 | J27: R5-Susmita | K27: Masud Rana | L27: NHP386 | M27: 2390739 | N27: 2026050 | O27: 61 | Q27: R5-Susmita | R27: Masud Rana | S27: NHP386 | T27: 0 | X27: R5-Susmita | Y27: Masud Rana | Z27: NHP386 | AA27: 35994 | AB27: 30503.39 | AC27: 6
A28: Satyaki Acharjee | B28: NHP826 | C28: Masud Rana | D28: R5-Susmita | E28: Susmita Paul | F28: Biswadip Sarkar | G28: 50 | H28: 65 | J28: R5-Susmita | K28: Nildeep Dasgupta | L28: NHP807 | M28: 680078 | N28: 576337.29 | O28: 22 | Q28: R5-Susmita | R28: Nildeep Dasgupta | S28: NHP807 | T28: 125994 | U28: 106774.58 | V28: 6 | X28: R5-Susmita | Y28: Nildeep Dasgupta | Z28: NHP807 | AA28: 41993 | AB28: 35587.288 | AC28: 7
A29: Sriti Jaiswal | B29: NHP553 | D29: R5-Susmita | E29: Susmita Paul | F29: Biswadip Sarkar | G29: 65 | H29: 84.5 | J29: R5-Susmita | K29: Nilotpal Sharma | L29: NHP675 | M29: 1659358 | N29: 1406235.6 | O29: 42 | Q29: R5-Susmita | R29: Nilotpal Sharma | S29: NHP675 | T29: 0 | X29: R5-Susmita | Y29: Nilotpal Sharma | Z29: NHP675 | AA29: 24996 | AB29: 21183.051 | AC29: 4
A30: Subash Debnath | B30: NHP148 | D30: R5-Susmita | E30: Susmita Paul | F30: Biswadip Sarkar | G30: 65 | H30: 84.5 | J30: R5-Susmita | K30: Sambit Kumar | L30: NHP717 | M30: 1854207 | N30: 1571361.9 | O30: 43 | Q30: R5-Susmita | R30: Sambit Kumar | S30: NHP717 | T30: 0 | X30: R5-Susmita | Y30: Sambit Kumar | Z30: NHP717 | AA30: 23996 | AB30: 20335.593 | AC30: 4
A31: Susmita Paul | B31: NHP166 | D31: R5-Susmita | E31: Susmita Paul | F31: Biswadip Sarkar | G31: 70 | H31: 91 | J31: R5-Susmita | K31: Sriti Jaiswal | L31: NHP553 | M31: 3472358 | N31: 2942676.3 | O31: 92 | Q31: R5-Susmita | R31: Sriti Jaiswal | S31: NHP553 | T31: 0 | X31: R5-Susmita | Y31: Sriti Jaiswal | Z31: NHP553 | AA31: 96984 | AB31: 82189.831 | AC31: 16
A32: Akar Srivastava | B32: NHP169 | D32: R6-Independent(Biswadip) | F32: Biswadip Sarkar | G32: 50 | H32: 65 | J32: R5-Susmita | K32: Subash Debnath | L32: NHP148 | M32: 3447765 | N32: 2921834.7 | O32: 85 | Q32: R5-Susmita | R32: Subash Debnath | S32: NHP148 | T32: 0 | X32: R5-Susmita | Y32: Subash Debnath | Z32: NHP148 | AA32: 41993 | AB32: 35587.288 | AC32: 7
A33: Faiq Khan | B33: NHP155 | D33: R6-Independent(Biswadip) | F33: Biswadip Sarkar | G33: 60 | H33: 78 | J33: R5-Susmita | K33: Susmita Paul | L33: NHP166 | M33: 4975016 | N33: 4216115.3 | O33: 134 | Q33: R5-Susmita | R33: Susmita Paul | S33: NHP166 | T33: 0 | X33: R5-Susmita | Y33: Susmita Paul | Z33: NHP166 | AA33: 119980 | AB33: 101677.97 | AC33: 20
A34: Manoj Sharma | B34: NHP470 | D34: R6-Independent(Biswadip) | F34: Biswadip Sarkar | G34: 60 | H34: 78 | J34: R5-Susmita | K34: Satyaki Acharjee | L34: NHP826 | M34: 1043673 | N34: 884468.64 | O34: 27 | Q34: R5-Susmita | R34: Satyaki Acharjee | S34: NHP826 | T34: 0 | X34: R5-Susmita | Y34: Satyaki Acharjee | Z34: NHP826 | AA34: 17997 | AB34: 15251.695 | AC34: 3
A35: Mudit Raj | B35: NHP142 | D35: R6-Independent(Biswadip) | F35: Biswadip Sarkar | G35: 60 | H35: 78 | J35: R5-Susmita Total | M35: 19523194 | N35: 16545080 | O35: 506 | Q35: R5-Susmita Total | T35: 125994 | U35: 106774.58 | V35: 6 | X35: R5-Susmita Total | AA35: 403933 | AB35: 342316.1 | AC35: 67
A36: Prashant Vaibhav | B36: NHP676 | D36: R6-Independent(Biswadip) | F36: Biswadip Sarkar | G36: 70 | H36: 91 | J36: R6-Independent(Biswadip) | K36: Akar Srivastava | L36: NHP169 | M36: 2046854 | N36: 1734622 | O36: 46 | Q36: R6-Independent(Biswadip) | R36: Akar Srivastava | S36: NHP169 | T36: 0 | X36: R6-Independent(Biswadip) | Y36: Akar Srivastava | Z36: NHP169 | AA36: 11998 | AB36: 10167.797 | AC36: 2
A37: Suraj Singh | B37: NHP446 | D37: R6-Independent(Biswadip) | F37: Biswadip Sarkar | G37: 65 | H37: 84.5 | J37: R6-Independent(Biswadip) | K37: Faiq Khan | L37: NHP155 | M37: 1380666 | N37: 1170055.9 | O37: 34 | Q37: R6-Independent(Biswadip) | R37: Faiq Khan | S37: NHP155 | T37: 116998 | U37: 99150.847 | V37: 2 | X37: R6-Independent(Biswadip) | Y37: Faiq Khan | Z37: NHP155 | AA37: 47992 | AB37: 40671.186 | AC37: 8
A38: Vinod Pathania | B38: NHP151 | D38: R6-Independent(Biswadip) | F38: Biswadip Sarkar | G38: 50 | H38: 65 | J38: R6-Independent(Biswadip) | K38: Manoj Sharma | L38: NHP470 | M38: 895175 | N38: 758622.88 | O38: 25 | Q38: R6-Independent(Biswadip) | R38: Manoj Sharma | S38: NHP470 | T38: 0 | X38: R6-Independent(Biswadip) | Y38: Manoj Sharma | Z38: NHP470 | AA38: 35994 | AB38: 30503.39 | AC38: 6
A39: Manasvi D | B39: NHP674 | D39: R7-Sufiyan | E39: Sufiyan Ansari | F39: Rajat Sharma | G39: 60 | H39: 78 | J39: R6-Independent(Biswadip) | K39: Mudit Raj | L39: NHP142 | M39: 2690736 | N39: 2280284.7 | O39: 64 | Q39: R6-Independent(Biswadip) | R39: Mudit Raj | S39: NHP142 | T39: 137997 | U39: 116946.61 | V39: 3 | X39: R6-Independent(Biswadip) | Y39: Mudit Raj | Z39: NHP142 | AA39: 49992 | AB39: 42366.102 | AC39: 8
A40: Paras Doifode | B40: NHP551 | D40: R7-Sufiyan | E40: Sufiyan Ansari | F40: Rajat Sharma | G40: 70 | H40: 91 | J40: R6-Independent(Biswadip) | K40: Prashant Vaibhav | L40: NHP676 | M40: 5457486 | N40: 4624988.1 | O40: 114 | Q40: R6-Independent(Biswadip) | R40: Prashant Vaibhav | S40: NHP676 | T40: 0 | X40: R6-Independent(Biswadip) | Y40: Prashant Vaibhav | Z40: NHP676 | AA40: 47992 | AB40: 40671.186 | AC40: 8
...

Sheet Incentive Report- Output
J1: =SUMIF(D:D,"R10",O:O) -> 1.1373777e+08
A2: 46113
A3: PARTICULARS | E3: BDE | T3: TM/SR BDE | X3: ZONE - RM | AB3: Other Incenitves/Penalty | AC3: Final Incentives Apr 2026 | AH3: PENALTY FOR UNDERUTILIZING THE SALES COUPONS ( LESS THAN 80% ) | AI3: PARTICULARS | AL3: Penalty Per Employee
A4: Name | B4: Employee ID | C4: Designation | D4: Zone | E4: BDE Target Units | F4: Winner Units | G4: Gross Sales Count | H4: Disqaulified Sales Count | I4: Foundation Sales Count | J4: Achieved Units RM & TM | K4: Achieved units % BDE | L4: Target Revenue - NET | M4: Achieved Revenue (Including GST)- GROSS | N4: Achieved Revenue (W/o GST) - NET Disqualified Sales | O4: Achieved Revenue (W/o GST)- NET BDE | P4: Achieved Revenue % | Q4: Highest of units and Revenue % | R4: Incremental slab % | S4: BDE Incentive | T4: TM/SR BDE Target (Revenue) | U4: TM/SR BDE Achieved (Revenue) | V4: TM/SR BDE Achieved % | W4: TM/SR BDE Incentive | X4: Zone target (units) | Y4: Zone Achieved (units) | Z4: Zone Achieved % | AA4: RM Incentive - Quaterly Payout | AB4: Spot Incenitve / Half Yearly Performance Incentive/Penalty/Best RM Reward | AC4: Prior Period Adjustments | AD4: Accumulation Above 2lacs Payable at Year end | AE4: Net Payable this month | AF4: Incentive of the Month | AI4: Name | AJ4: =B4 -> Employee ID | AK4: Zone | AL4: Gross Incentive | AM4: Net Incentive ( after penalty ) | AN4: Penalty
A5: Ajeet Pandey | B5: NHP374 | C5: RM | D5: R1 | E5: =ROUND(SUMIF('Target Achieved- Input'!$B$2:$B$90,'Incentive Report- Output'!B5,'Target Achieved- Input'!$G$2:$G$90),0) -> 60 | F5: =ROUND(SUMIF('Target Achieved- Input'!$B$2:$B$90,'Incentive Report- Output'!B5,'Target Achieved- Input'!$H$2:$H$90),0) -> 78 | G5: =SUMIF('Target Achieved- Input'!$L$2:$L$90,'Incentive Report- Output'!B5,'Target Achieved- Input'!$O$2:$O$90) -> 37 | H5: =SUMIF('Target Achieved- Input'!$S$2:$S$90,'Incentive Report- Output'!B5,'Target Achieved- Input'!$V$2:$V$90) -> 5 | I5: =SUMIF('Target Achieved- Input'!$L$2:$L$90,'Incentive Report- Output'!B5,'Target Achieved- Input'!$AC$2:$AC$90) -> 2 | J5: =G5-H5 -> 32 | K5: =IFERROR(J5/E5,0) -> 0.53333333 | L5: =E5*33000 -> 1980000 | M5: =SUMIF('Target Achieved- Input'!$L$2:$L$90,'Incentive Report- Output'!B5,'Target Achieved- Input'!$M$2:$M$90) -> 1387763 | N5: =SUMIF('Target Achieved- Input'!$S$2:$S$90,'Incentive Report- Output'!B5,'Target Achieved- Input'!$U$2:$U$90) -> 169487.29 | O5: =SUMIF('Target Achieved- Input'!$L$2:$L$90,'Incentive Report- Output'!B5,'Target Achieved- Input'!$N$2:$N$90)-N5 -> 1006583.1 | P5: =IFERROR(O5/L5,0) -> 0.50837528 | Q5: =P5 -> 0.50837528 | R5: 0 | S5: =(LOOKUP(Q5,Policy!$L$12:$M$16)+R5)*O5 -> 5032.9153 | X5: =E10 -> 280 | Y5: =J10 -> 200 | Z5: =Y5/X5 -> 0.71428571 | AA5: 0 | AB5: 0 | AC5: 0 | AD5: =IF(AF5>200000,AF5-200000,0) -> 0 | AE5: =AF5-AD5 -> 5032.9153 | AF5: =S5+W5+AB5+AC5 -> 5032.9153 | AI5: Ajeet Pandey | AJ5: NHP374 | AK5: R1 | AL5: 5880.3517 | AM5: =AF5 -> 5032.9153 | AN5: =AL5-AM5 -> 847.43644
A6: Ankit Madan | B6: NHP291 | C6: BDE | D6: R1 | E6: =ROUND(SUMIF('Target Achieved- Input'!$B$2:$B$90,'Incentive Report- Output'!B6,'Target Achieved- Input'!$G$2:$G$90),0) -> 60 | F6: =ROUND(SUMIF('Target Achieved- Input'!$B$2:$B$90,'Incentive Report- Output'!B6,'Target Achieved- Input'!$H$2:$H$90),0) -> 78 | G6: =SUMIF('Target Achieved- Input'!$L$2:$L$90,'Incentive Report- Output'!B6,'Target Achieved- Input'!$O$2:$O$90) -> 52 | H6: =SUMIF('Target Achieved- Input'!$S$2:$S$90,'Incentive Report- Output'!B6,'Target Achieved- Input'!$V$2:$V$90) -> 2 | I6: =SUMIF('Target Achieved- Input'!$L$2:$L$90,'Incentive Report- Output'!B6,'Target Achieved- Input'!$AC$2:$AC$90) -> 5 | J6: =G6-H6 -> 50 | K6: =IFERROR(J6/E6,0) -> 0.83333333 | L6: =E6*33000 -> 1980000 | M6: =SUMIF('Target Achieved- Input'!$L$2:$L$90,'Incentive Report- Output'!B6,'Target Achieved- Input'!$M$2:$M$90) -> 1999998 | N6: =SUMIF('Target Achieved- Input'!$S$2:$S$90,'Incentive Report- Output'!B6,'Target Achieved- Input'!$U$2:$U$90) -> 56481.356 | O6: =SUMIF('Target Achieved- Input'!$L$2:$L$90,'Incentive Report- Output'!B6,'Target Achieved- Input'!$N$2:$N$90)-N6 -> 1638432.2 | P6: =IFERROR(O6/L6,0) -> 0.82749101 | Q6: =P6 -> 0.82749101 | R6: 0 | S6: =(LOOKUP(Q6,Policy!$L$12:$M$16)+R6)*O6 -> 16384.322 | AA6: 0 | AB6: 0 | AC6: 0 | AD6: =IF(AF6>200000,AF6-200000,0) -> 0 | AE6: =AF6-AD6 -> 16384.322 | AF6: =S6+W6+AB6+AC6 -> 16384.322 | AI6: Ankit Madan | AJ6: NHP291 | AK6: R1 | AL6: 16949.136 | AM6: =AF6 -> 16384.322 | AN6: =AL6-AM6 -> 564.81356
A7: Sachin Sharma | B7: NHP698 | C7: BDE | D7: R1 | E7: =ROUND(SUMIF('Target Achieved- Input'!$B$2:$B$90,'Incentive Report- Output'!B7,'Target Achieved- Input'!$G$2:$G$90),0) -> 50 | F7: =ROUND(SUMIF('Target Achieved- Input'!$B$2:$B$90,'Incentive Report- Output'!B7,'Target Achieved- Input'!$H$2:$H$90),0) -> 65 | G7: =SUMIF('Target Achieved- Input'!$L$2:$L$90,'Incentive Report- Output'!B7,'Target Achieved- Input'!$O$2:$O$90) -> 28 | H7: =SUMIF('Target Achieved- Input'!$S$2:$S$90,'Incentive Report- Output'!B7,'Target Achieved- Input'!$V$2:$V$90) -> 4 | I7: =SUMIF('Target Achieved- Input'!$L$2:$L$90,'Incentive Report- Output'!B7,'Target Achieved- Input'!$AC$2:$AC$90) -> 7 | J7: =G7-H7 -> 24 | K7: =IFERROR(J7/E7,0) -> 0.48 | L7: =E7*33000 -> 1650000 | M7: =SUMIF('Target Achieved- Input'!$L$2:$L$90,'Incentive Report- Output'!B7,'Target Achieved- Input'!$M$2:$M$90) -> 982522 | N7: =SUMIF('Target Achieved- Input'!$S$2:$S$90,'Incentive Report- Output'!B7,'Target Achieved- Input'!$U$2:$U$90) -> 120335.59 | O7: =SUMIF('Target Achieved- Input'!$L$2:$L$90,'Incentive Report- Output'!B7,'Target Achieved- Input'!$N$2:$N$90)-N7 -> 712310.17 | P7: =IFERROR(O7/L7,0) -> 0.43170313 | Q7: =P7 -> 0.43170313 | R7: 0 | S7: =(LOOKUP(Q7,Policy!$L$12:$M$16)+R7)*O7 -> 0 | AA7: 0 | AB7: 0 | AC7: 0 | AD7: =IF(AF7>200000,AF7-200000,0) -> 0 | AE7: =AF7-AD7 -> 0 | AF7: =S7+W7+AB7+AC7 -> 0 | AI7: Sachin Sharma | AJ7: NHP698 | AK7: R1 | AL7: 4163.2288 | AM7: =AF7 -> 0 | AN7: =AL7-AM7 -> 4163.2288
A8: Shariq Bhat | B8: NHP679 | C8: BDE | D8: R1 | E8: =ROUND(SUMIF('Target Achieved- Input'!$B$2:$B$90,'Incentive Report- Output'!B8,'Target Achieved- Input'!$G$2:$G$90),0) -> 50 | F8: =ROUND(SUMIF('Target Achieved- Input'!$B$2:$B$90,'Incentive Report- Output'!B8,'Target Achieved- Input'!$H$2:$H$90),0) -> 65 | G8: =SUMIF('Target Achieved- Input'!$L$2:$L$90,'Incentive Report- Output'!B8,'Target Achieved- Input'!$O$2:$O$90) -> 45 | H8: =SUMIF('Target Achieved- Input'!$S$2:$S$90,'Incentive Report- Output'!B8,'Target Achieved- Input'!$V$2:$V$90) -> 1 | I8: =SUMIF('Target Achieved- Input'!$L$2:$L$90,'Incentive Report- Output'!B8,'Target Achieved- Input'!$AC$2:$AC$90) -> 1 | J8: =G8-H8 -> 44 | K8: =IFERROR(J8/E8,0) -> 0.88 | L8: =E8*33000 -> 1650000 | M8: =SUMIF('Target Achieved- Input'!$L$2:$L$90,'Incentive Report- Output'!B8,'Target Achieved- Input'!$M$2:$M$90) -> 1616955 | N8: =SUMIF('Target Achieved- Input'!$S$2:$S$90,'Incentive Report- Output'!B8,'Target Achieved- Input'!$U$2:$U$90) -> 33897.458 | O8: =SUMIF('Target Achieved- Input'!$L$2:$L$90,'Incentive Report- Output'!B8,'Target Achieved- Input'!$N$2:$N$90)-N8 -> 1336403.4 | P8: =IFERROR(O8/L8,0) -> 0.80994145 | Q8: =P8 -> 0.80994145 | R8: 0 | S8: =(LOOKUP(Q8,Policy!$L$12:$M$16)+R8)*O8 -> 13364.034 | AA8: 0 | AB8: 0 | AC8: 0 | AD8: =IF(AF8>200000,AF8-200000,0) -> 0 | AE8: =AF8-AD8 -> 13364.034 | AF8: =S8+W8+AB8+AC8 -> 13364.034 | AI8: Shariq Bhat | AJ8: NHP679 | AK8: R1 | AL8: 13703.008 | AM8: =AF8 -> 13364.034 | AN8: =AL8-AM8 -> 338.97458
